Workbook

Sheet Startegy Changes Mod or Fun (QT
A3: Fund or Model | B3: Strategy Detail | C3: Portfolios name | D3: Flows mln 1Q € | E3: Sum of % Change Flows | F3: Difference In AUM mln Q1 €
A4: Fund | D4: -519.25036 | E4: -0.12505604 | F4: -350.87
B5: Bond | D5: -2.9774607 | E5: -0.04010165 | F5: -2.9849541
B6: Conservative | D6: -7.3841967 | E6: -0.028701929 | F6: -5.1672111
B7: Equity | D7: -14.921085 | E7: -0.12510663 | F7: -18.078061
B8: Flexible | D8: -26.306785 | E8: -0.071493562 | F8: -32.02505
B9: Growth | D9: 25.096397 | E9: 0.1442819 | F9: 27.735835
B10: Income | D10: -11.006052 | E10: -0.037418931 | F10: -16.633531
B11: Moderate | D11: -9.826379 | E11: -0.022059036 | F11: -1.6296295
B12: Risk Accumulation | D12: -335.01257 | E12: -0.18945034 | F12: -420.76862
B13: Thematic | D13: -136.91224 | E13: -0.21014083 | F13: 118.68122
A14: Model | D14: -307.44577 | E14: -0.035126256 | F14: -88.065456
B15: Capital Guaranteed | D15: -65.534486 | E15: -0.054219271 | F15: -44.165264
B16: Capital Protection | D16: -0.0873133 | E16: -0.012552394 | F16: -0.01984
B17: Conservative | D17: -20.27235 | E17: -0.030977101 | F17: -17.236822
B18: Equity | D18: -35.848827 | E18: -0.011128298 | F18: 100.7319
B19: Flexible | D19: -130.64609 | E19: -0.10657308 | F19: -120.7386
B20: Growth | D20: -11.94981 | E20: -0.026006461 | F20: 4.694794
B21: Income | D21: -54.349645 | E21: -0.086591532 | F21: -57.063289
B22: Moderate | D22: -3.712064 | E22: -0.021657603 | F22: -2.638989
B23: Risk Accumulation | D23: -0.6752106 | E23: -0.14351059 | F23: -0.468905
B24: Thematic | D24: 15.630024 | E24: 0.013336587 | F24: 48.83956
A25: Grand Total | D25: -826.69614 | E25: -0.064061467 | F25: -438.93546

Sheet Startegy Changes (QTD)
A3: Strategy Detail | B3: Flows mln Q1 € | C3: Difference In AUM mln Q1 €
A4: Bond | B4: -2.9774607 | C4: -2.9849541
A5: Capital Guaranteed | B5: -65.534486 | C5: -44.165264
A6: Capital Protection | B6: -0.0873133 | C6: -0.01984
A7: Conservative | B7: -27.656547 | C7: -22.404033
A8: Equity | B8: -50.769913 | C8: 82.653837
A9: Flexible | B9: -156.95288 | C9: -152.76365
A10: Growth | B10: 13.146587 | C10: 32.430629
A11: Income | B11: -65.355696 | C11: -73.69682
A12: Moderate | B12: -13.538443 | C12: -4.2686185
A13: Risk Accumulation | B13: -335.68778 | C13: -421.23752
A14: Thematic | B14: -121.28221 | C14: 167.52078
A15: Grand Total | B15: -826.69614 | C15: -438.93546

Sheet Total Flows File (QTD)
A3: Portfolio Names | B3: Q123 Flows mln | C3: Q123 Difference In AUM | D3: Total Aum mln
A4: Capital Guaranteed | B4: -65.534486 | C4: -44.165264 | D4: 1208.6936
A5: ASSET ALLOCATION MODEL PROTETTO 80 | B5: -3.0901017 | C5: -2.123896 | D5: 105.97773
A6: CNP Dynamic Protection 80 | B6: -16.088829 | C6: -15.428341 | D6: 116.83255
A7: CNP THEMATIC PROTECTION 80 | B7: -10.521304 | C7: -6.386983 | D7: 195.36411
A8: CRV Dynamic Protection 80 | B8: -25.728394 | C8: -24.41432 | D8: 279.29356
A9: CRV THEMATIC PROTECTION 80 | B9: -11.494401 | C9: -4.918099 | D9: 307.50581
A10: CNP Protection 80 | B10: 0.36790654 | C10: 3.955401 | D10: 96.897819
A11: CRV Protection 80 | B11: 1.0206376 | C11: 5.150974 | D11: 106.82203
A12: Conservative | B12: -27.656547 | C12: -22.404033 | D12: 911.70197
A13: AMUNDI FUND SOLUTIONS - CONSERVATIVE | B13: -6.5852741 | C13: -4.3407969 | D13: 242.8063
A14: AMUNDI FUND SOLUTIONS - SABADELL URQUIJO ACUMULACION | B14: 0 | C14: 0 | D14: 6.9702262
A15: AMUNDI UNICREDIT PREM PORT- PRUDENTIAL | B15: -0.79892258 | C15: -0.82641419 | D15: 7.4952658
... A19: CAM STEP ONE | B19: 0 | C19: 0.001073 | D19: 0.078465
A20: CAM TREND 20 | B20: 0 | C20: 0 | D20: 0.023564 | H20: Funds | I20: Sum of Flows QTD mln | J20: Sum of Difference In AUM
A21: Life Program Bond | B21: -4.0474815 | C21: -3.214771 | D21: 86.278219 | H21: Univalore Stars Growth | I21: -176.18718 | J21: 117.43585
A22: PL Euro Bond 1 to 3 years | B22: -4.6289986 | C22: -3.879674 | D22: 87.573063 | H22: UNICREDIT EVOLUZIONE - REDDITO - A | I22: -50.325316 | J22: -51.999433
A23: PL Euro Bond over 3 years | B23: -0.18858553 | C23: 0.682015 | D23: 122.52132 | H23: CNP Dynamic Protection 80 | I23: -45.267894 | J23: -28.503755
A24: UL CAUTA | B24: -0.52380645 | C24: -0.286322 | D24: 27.311192 | H24: Unit Linked Multi Thematic Global Eq | I24: 10.325451 | J24: 212.69368
A25: UL PRUDENTE | B25: -0.66876387 | C25: -0.65926 | D25: 12.030736 | H25: AFS - BALANCED | I25: 13.817207 | J25: 21.290272
A26: UL PRUDENTE PIU | B26: -0.67315085 | C26: -0.613315 | D26: 15.554245 | H26: CRV THEMATIC PROTECTION 80 | I26: 17.180496 | J26: 26.976359
A27: UL_Prudente ERGO | B27: 0 | C27: 0 | D27: 0 | H27: AFS- CONSERVATIVE | I27: 41.471599 | J27: 39.459762
A28: UL_Prudente_+ ERGO | B28: 0 | C28: 0 | D28: 0 | H28: AFS - SABADELL URQUIJO CRECIMIENTO | I28: 43.818986 | J28: 44.247378
A29: UNIT LINKED E2 NEW | B29: -0.35063568 | C29: -0.30473 | D29: 7.616069 | H29: AFS - SABADELL URQUIJO ACUMULACION | I29: 104.94957 | J29: 98.074561
A30: UNIT LINKED E3 NEW | B30: -1.3791577 | C30: -1.380437 | D30: 72.484395 | H30: CNP Dynamic Protection 80 | I30: -45.267894 | J30: -28.503755
A31: Unit Linked OLD 4 | B31: -0.18290859 | C31: -0.182213 | D31: 1.067361 | H31: CRV Dynamic Protection 80 | I31: -145.17129 | J31: -109.32928
A32: SAXO EUROPE | B32: -7.0611691 | C32: -7.0611691 | D32: 192.19966 | H32: UL Life Income | I32: -78.218518 | J32: -75.150979
A33: AFS ICAV Planet ESG Conservative | H33: AMUNDI ELITE THEMATIC MA | I33: 325.57582 | J33: 325.57582
A34: Equity | B34: -50.769913 | C34: 82.653837 | D34: 3340.6785 | H34: UL Life Income 360 | I34: -155.45426 | J34: -174.27421
A35: Life Program Azionario Pacifico | B35: -0.07499342 | C35: -3.400871 | D35: 46.360523 | H35: Grand Total | I35: =SUM(I21:I34) -> -138.75323 | J35: =SUM(J21:J34) -> 417.99226
A36: PI INVESTMENT FUNDS - TACTICAL ALLOCATION FUND - H | B36: -0.44665158 | C36: -3.6036269 | D36: 53.160978
A37: UL Global Equity Dividend & Subordinated | B37: -32.352755 | C37: 23.919048 | D37: 1901.2516
A38: Unidiamond + Azionaria America | B38: 1.0081119 | C38: 79.886841 | D38: 1100.0065
A39: Unidiamond + Azionaria Intl | B39: -4.4291905 | C39: 0.32688 | D39: 173.7929
A40: Amundi Env and Climate Change Sol Fund | B40: -14.474434 | C40: -14.474434 | D40: 66.105969
A41: Flexible | B41: -156.95288 | C41: -152.76365 | D41: 1593.8429
A42: Amundi Invensys Broad Bond Portfolio | B42: 0 | C42: 3.4298218 | D42: 169.20099
A43: Life Program Flessibile | B43: -0.91659172 | C43: -0.811947 | D43: 24.819922
A44: PI INVESTMENT FUNDS - DYNAMIC ALLOCATION FUND - E | B44: -26.306785 | C44: -35.454872 | D44: 198.7592
A45: PL Income Clock | B45: -0.37310856 | C45: -0.299069 | D45: 33.652386
...

Sheet Startegy Changes Mod or Fun
A3: Fund or Model | B3: Strategy Detail | C3: Flows mln QTD Sept 24 € | D3: Difference In AUM mln QTD Nov 24 €
A4: Fund | C4: -519.25036 | D4: -350.87
B5: Bond | C5: -2.9774607 | D5: -2.9849541
B6: Conservative | C6: -7.3841967 | D6: -5.1672111
B7: Equity | C7: -14.921085 | D7: -18.078061
B8: Flexible | C8: -26.306785 | D8: -32.02505
B9: Growth | C9: 25.096397 | D9: 27.735835
B10: Income | C10: -11.006052 | D10: -16.633531
B11: Moderate | C11: -9.826379 | D11: -1.6296295
B12: Risk Accumulation | C12: -335.01257 | D12: -420.76862
B13: Thematic | C13: -136.91224 | D13: 118.68122
A14: Model | C14: -307.44577 | D14: -88.065456
B15: Capital Guaranteed | C15: -65.534486 | D15: -44.165264
B16: Capital Protection | C16: -0.0873133 | D16: -0.01984
B17: Conservative | C17: -20.27235 | D17: -17.236822
B18: Equity | C18: -35.848827 | D18: 100.7319
B19: Flexible | C19: -130.64609 | D19: -120.7386
B20: Growth | C20: -11.94981 | D20: 4.694794
B21: Income | C21: -54.349645 | D21: -57.063289
B22: Moderate | C22: -3.712064 | D22: -2.638989
B23: Risk Accumulation | C23: -0.6752106 | D23: -0.468905
B24: Thematic | C24: 15.630024 | D24: 48.83956
A25: Grand Total | C25: -826.69614 | D25: -438.93546

Sheet Total Flows File
A3: Portfolio Names | B3: QTD Sept 24 Flows mln | C3: QTD Sept 24 Difference In AUM | D3: QTD Sept 24 Total Aum mln
A4: Bond | B4: -2.9774607 | C4: -2.9849541 | D4: 74.247836
A5: PI INVESTMENT FUNDS - TACTICAL ALLOCATION BOND FUND - H | B5: -2.9774607 | C5: -2.9849541 | D5: 74.247836
A6: Capital Guaranteed | B6: -65.534486 | C6: -44.165264 | D6: 1208.6936
A7: ASSET ALLOCATION MODEL PROTETTO 80 | B7: -3.0901017 | C7: -2.123896 | D7: 105.97773
A8: CNP Dynamic Protection 80 | B8: -16.088829 | C8: -15.428341 | D8: 116.83255
A9: CNP THEMATIC PROTECTION 80 | B9: -10.521304 | C9: -6.386983 | D9: 195.36411
A10: CRV Dynamic Protection 80 | B10: -25.728394 | C10: -24.41432 | D10: 279.29356
A11: CRV THEMATIC PROTECTION 80 | B11: -11.494401 | C11: -4.918099 | D11: 307.50581
A12: CNP Protection 80 | B12: 0.36790654 | C12: 3.955401 | D12: 96.897819
A13: CRV Protection 80 | B13: 1.0206376 | C13: 5.150974 | D13: 106.82203
A14: Capital Protection | B14: -0.0873133 | C14: -0.01984 | D14: 6.955908
A15: CAM Agosto | B15: -0.00162516 | C15: -0.000375 | D15: 0.142698
... A19: CAM Gennaio | B19: -0.00174022 | C19: -0.000137 | D19: 0.187778
A20: CAM Giugno | B20: -0.00275801 | C20: 0.002991 | D20: 0.634676 | H20: Funds | I20: Sum of Flows QTD mln | J20: Sum of Difference In AUM
A21: CAM Luglio | B21: 0 | C21: -0.000775 | D21: 0.077561 | H21: Univalore Stars Growth | I21: -176.18718 | J21: 117.43585
A22: CAM Maggio | B22: -0.0016057 | C22: -0.000323 | D22: 0.134904 | H22: UNICREDIT EVOLUZIONE - REDDITO - A | I22: -50.325316 | J22: -51.999433
A23: CAM Marzo | B23: -0.00164449 | C23: -0.000266 | D23: 0.154948 | H23: CNP Dynamic Protection 80 | I23: -45.267894 | J23: -28.503755
A24: CAM Novembre | B24: -0.00195811 | C24: 0.000944 | D24: 0.279016 | H24: Unit Linked Multi Thematic Global Eq | I24: 10.325451 | J24: 212.69368
A25: CAM Ottobre | B25: -0.001209 | C25: -0.000946 | D25: 0.028074 | H25: AFS - BALANCED | I25: 13.817207 | J25: 21.290272
A26: CAM Settembre | B26: -0.00057969 | C26: -0.000434 | D26: 0.016557 | H26: CRV THEMATIC PROTECTION 80 | I26: 17.180496 | J26: 26.976359
A27: Conservative | B27: -27.656547 | C27: -22.404033 | D27: 911.70197 | H27: AFS- CONSERVATIVE | I27: 41.471599 | J27: 39.459762
A28: AMUNDI FUND SOLUTIONS - CONSERVATIVE | B28: -6.5852741 | C28: -4.3407969 | D28: 242.8063 | H28: AFS - SABADELL URQUIJO CRECIMIENTO | I28: 43.818986 | J28: 44.247378
A29: AMUNDI FUND SOLUTIONS - SABADELL URQUIJO ACUMULACION | B29: 0 | C29: 0 | D29: 6.9702262 | H29: AFS - SABADELL URQUIJO ACUMULACION | I29: 104.94957 | J29: 98.074561
A30: AMUNDI UNICREDIT PREM PORT- PRUDENTIAL | B30: -0.79892258 | C30: -0.82641419 | D30: 7.4952658 | H30: CNP Dynamic Protection 80 | I30: -45.267894 | J30: -28.503755
A31: CAM ARES RISPARMIO OBBLIGAZ. M | B31: -0.56769213 | C31: -0.338342 | D31: 29.605967 | H31: CRV Dynamic Protection 80 | I31: -145.17129 | J31: -109.32928
A32: CAM OBBLIGAZIONARIA EURO | B32: 0 | C32: 0 | D32: 0.002649 | H32: UL Life Income | I32: -78.218518 | J32: -75.150979
... A34: CAM STEP ONE | B34: 0 | C34: 0.001073 | D34: 0.078465 | H34: UL Life Income 360 | I34: -155.45426 | J34: -174.27421
A35: CAM TREND 20 | B35: 0 | C35: 0 | D35: 0.023564 | H35: Grand Total | I35: =SUM(I21:I34) -> -138.75323 | J35: =SUM(J21:J34) -> 417.99226
A36: Life Program Bond | B36: -4.0474815 | C36: -3.214771 | D36: 86.278219
A37: PL Euro Bond 1 to 3 years | B37: -4.6289986 | C37: -3.879674 | D37: 87.573063
A38: PL Euro Bond over 3 years | B38: -0.18858553 | C38: 0.682015 | D38: 122.52132
A39: UL CAUTA | B39: -0.52380645 | C39: -0.286322 | D39: 27.311192
A40: UL PRUDENTE | B40: -0.66876387 | C40: -0.65926 | D40: 12.030736
A41: UL PRUDENTE PIU | B41: -0.67315085 | C41: -0.613315 | D41: 15.554245
A42: UL_Prudente ERGO | B42: 0 | C42: 0 | D42: 0
A43: UL_Prudente_+ ERGO | B43: 0 | C43: 0 | D43: 0
A44: UNIT LINKED E2 NEW | B44: -0.35063568 | C44: -0.30473 | D44: 7.616069
A45: UNIT LINKED E3 NEW | B45: -1.3791577 | C45: -1.380437 | D45: 72.484395
A46: Unit Linked OLD 4 | B46: -0.18290859 | C46: -0.182213 | D46: 1.067361 | H46: 1997 | I46: 2022 | J46: =I46-H46 -> 25
...

Sheet Startegy Changes
A3: Fund or Model | B3: Strategy Detail | C3: Portfolios name | D3: Flows mln € | E3: Sum of % Change Flows | F3: Change In AUM mln € | G3: Total AUM
A4: Fund | D4: -519.25036 | E4: -0.12505604 | F4: -350.87 | G4: 4152.1414
B5: Bond | D5: -2.9774607 | E5: -0.04010165 | F5: -2.9849541 | G5: 74.247836
C6: PI INVESTMENT FUNDS - TACTICAL ALLOCATION BOND FUND - H | D6: -2.9774607 | E6: -0.04010165 | F6: -2.9849541 | G6: 74.247836
B7: Conservative | D7: -7.3841967 | E7: -0.028701929 | F7: -5.1672111 | G7: 257.27179
C8: AFS ICAV Planet ESG Conservative | E8: #DIV/0!
C9: AMUNDI FUND SOLUTIONS - CONSERVATIVE | D9: -6.5852741 | E9: -0.027121513 | F9: -4.3407969 | G9: 242.8063
C10: AMUNDI FUND SOLUTIONS - SABADELL URQUIJO ACUMULACION | D10: 0 | E10: 0 | F10: 0 | G10: 6.9702262
C11: AMUNDI UNICREDIT PREM PORT- PRUDENTIAL | D11: -0.79892258 | E11: -0.10659029 | F11: -0.82641419 | G11: 7.4952658
B12: Equity | D12: -14.921085 | E12: -0.12510663 | F12: -18.078061 | G12: 119.26695
C13: Amundi Env and Climate Change Sol Fund | D13: -14.474434 | E13: -0.21895804 | F13: -14.474434 | G13: 66.105969
C14: PI INVESTMENT FUNDS - TACTICAL ALLOCATION FUND - H | D14: -0.44665158 | E14: -0.0084018691 | F14: -3.6036269 | G14: 53.160978
B15: Flexible | D15: -26.306785 | E15: -0.071493562 | F15: -32.02505 | G15: 367.9602
C16: Amundi Invensys Broad Bond Portfolio | D16: 0 | E16: 0 | F16: 3.4298218 | G16: 169.20099
C17: PI INVESTMENT FUNDS - DYNAMIC ALLOCATION FUND - E | D17: -26.306785 | E17: -0.13235506 | F17: -35.454872 | G17: 198.7592
B18: Growth | D18: 25.096397 | E18: 0.1442819 | F18: 27.735835 | G18: 173.94003
C19: AFS ICAV Planet ESG Dynamic | E19: #DIV/0!
C20: AMUNDI FUND SOLUTIONS - DIVERSIFIED GROWTH - A | D20: -1.1998128 | E20: -0.014313611 | F20: -1.8619051 | G20: 83.823204
C21: AMUNDI FUND SOLUTIONS - SABADELL URQUIJO CRECIMIENTO | D21: 0 | E21: 0 | F21: 0 | G21: 3.9275611
C22: AMUNDI UNICREDIT PREMIUM PORT - DYNAMIC | D22: -1.6565681 | E22: -0.028445535 | F22: 1.6449617 | G22: 58.236487
C23: AMUNDI-FUNDACION CAJA NAVARRA DYNAMIC | D23: 27.952778 | E23: 1 | F23: 27.952778 | G23: 27.952778
B24: Income | D24: -11.006052 | E24: -0.037418931 | F24: -16.633531 | G24: 294.13057
C25: Amundi Fund Solutions - Diversified Income Best Select 2022 | D25: -4.8674647 | E25: -0.035677734 | F25: -1.3859767 | G25: 136.42864
C26: PI INVESTMENT FUNDS - TACTICAL ALLOCATION PILLAR - E | D26: -6.1385868 | E26: -0.10307136 | F26: -15.268212 | G26: 59.556669
C27: THE TRUSTHOUSE FDN CPI+4% MULTI-AST PTF | D27: 0 | E27: 0 | F27: 0.02065766 | G27: 98.145265
B28: Moderate | D28: -9.826379 | E28: -0.022059036 | F28: -1.6296295 | G28: 445.45822
C29: AFS ICAV Planet ESG Balanced | E29: #DIV/0!
C30: AMUNDI FUND SOLUTIONS - BALANCED | D30: -4.4015434 | E30: -0.013584615 | F30: 0.85909412 | G30: 324.00944
C31: AMUNDI UNICREDIT PREM PORT- MULTI ASSET | D31: -5.4248356 | E31: -0.044667682 | F31: -2.4887237 | G31: 121.44878
B32: Risk Accumulation | D32: -335.01257 | E32: -0.18945034 | F32: -420.76862 | G32: 1768.3397
C33: AMUNDI SENTIERO SOSTENIBILE | D33: -10.126505 | E33: -0.034880113 | F33: -7.3314559 | G33: 290.32318
C34: AMUNDI SOLUZIONI ITALIA - PROGETTO AZIONE CAMBIAMENTO CLIMATICO - E | E34: #DIV/0!
C35: AMUNDI SOLUZIONI ITALIA - PROGETTO AZIONE CAMBIAMENTO CLIMATICO (II) - E | E35: #DIV/0!
C36: AMUNDI SOLUZIONI ITALIA - PROGETTO AZIONE INFRASTRUTTURE SOSTENIBILI | D36: -114.98841 | E36: -0.34309857 | F36: -138.67363 | G36: 335.14686
C37: AMUNDI SOLUZIONI ITALIA - PROGETTO AZIONE INFRASTRUTTURE SOSTENIBILI (II) | D37: -68.314788 | E37: -0.21387638 | F37: -89.223301 | G37: 319.41249
C38: AMUNDI SOLUZIONI ITALIA - PROGETTO AZIONE MEGATREND - E | E38: #DIV/0!
C39: AMUNDI SOLUZIONI ITALIA - PROGETTO AZIONE MEGATREND (II) - E | E39: #DIV/0!
C40: ASI - PROGETTO AZIONE ENERGY TRANSITION | D40: -75.897228 | E40: -0.16792157 | F40: -103.51484 | G40: 451.98023
C41: ASI - PROGETTO AZIONE ENERGY TRANSITION (II) | D41: -47.534278 | E41: -0.17102462 | F41: -63.884148 | G41: 277.93822
C42: ASI - PROGETTO AZIONE FUTURO GREEN | D42: -18.151357 | E42: -0.19405172 | F42: -18.141244 | G42: 93.538758
...

Sheet Startegy Changes (Model Fund)
A3: Fund or Model | B3: Strategy Detail | C3: Flows mln € | D3: % Change Flows | E3: Change In AUM mlnl €
A4: Fund | C4: -519.25036 | D4: -0.12505604 | E4: -350.87
B5: Bond | C5: -2.9774607 | D5: -0.04010165 | E5: -2.9849541
B6: Conservative | C6: -7.3841967 | D6: -0.028701929 | E6: -5.1672111
B7: Equity | C7: -14.921085 | D7: -0.12510663 | E7: -18.078061
B8: Flexible | C8: -26.306785 | D8: -0.071493562 | E8: -32.02505
B9: Growth | C9: 25.096397 | D9: 0.1442819 | E9: 27.735835
B10: Income | C10: -11.006052 | D10: -0.037418931 | E10: -16.633531
B11: Moderate | C11: -9.826379 | D11: -0.022059036 | E11: -1.6296295
B12: Risk Accumulation | C12: -335.01257 | D12: -0.18945034 | E12: -420.76862
B13: Thematic | C13: -136.91224 | D13: -0.21014083 | E13: 118.68122
A14: Model | C14: -307.44577 | D14: -0.035126256 | E14: -88.065456
B15: Capital Guaranteed | C15: -65.534486 | D15: -0.054219271 | E15: -44.165264
B16: Capital Protection | C16: -0.0873133 | D16: -0.012552394 | E16: -0.01984
B17: Conservative | C17: -20.27235 | D17: -0.030977101 | E17: -17.236822
B18: Equity | C18: -35.848827 | D18: -0.011128298 | E18: 100.7319
B19: Flexible | C19: -130.64609 | D19: -0.10657308 | E19: -120.7386
B20: Growth | C20: -11.94981 | D20: -0.026006461 | E20: 4.694794
B21: Income | C21: -54.349645 | D21: -0.086591532 | E21: -57.063289
B22: Moderate | C22: -3.712064 | D22: -0.021657603 | E22: -2.638989
B23: Risk Accumulation | C23: -0.6752106 | D23: -0.14351059 | E23: -0.468905
B24: Thematic | C24: 15.630024 | D24: 0.013336587 | E24: 48.83956
A25: Grand Total | C25: -826.69614 | D25: -0.064061467 | E25: -438.93546

Sheet Startegy Changes (List)
A3: Strategy Detail | B3: Portfolios name | C3: Flows mln € | D3: Sum of % Change Flows | E3: Difference In AUM mln € | F3: Total AUM | I3: FILTER?
A4: Bond | C4: -2.9774607 | D4: -0.04010165 | E4: -2.9849541 | F4: 74.247836
A5: Capital Guaranteed | C5: -65.534486 | D5: -0.054219271 | E5: -44.165264 | F5: 1208.6936
A6: Conservative | C6: -14.969172 | D6: -0.031862019 | E6: -12.514702 | F6: 469.81242
A7: Equity | C7: -47.273841 | D7: -0.023396885 | E7: 5.8409874 | F7: 2020.5186
A8: Flexible | C8: -155.0188 | D8: -0.11449889 | E8: -154.46564 | F8: 1353.8892
A9: Growth | C9: 24.190522 | D9: 0.12862072 | E9: 26.785796 | F9: 188.07641
A10: Income | C10: -65.355696 | D10: -0.072314772 | E10: -71.062351 | F10: 903.76689
A11: Moderate | C11: -10.440492 | D11: -0.022897047 | E11: -2.2270415 | F11: 455.97545
A12: Risk Accumulation | C12: -335.35307 | D12: -0.18913966 | E12: -421.23752 | F12: 1773.0447
A13: Thematic | C13: -121.28221 | D13: -0.066860853 | E13: 172.16372 | F13: 1813.9495
N56: 6.7471388e+08
N57: 7.0898621e+08
N58: =N56-N57 -> -34272339

Sheet AUM Data Sheet Dublin
A1: Original | B1: Added | C1: Original | D1: Added | E1: Added | F1: Added | G1: Added | H1: Added | I1: Added | J1: Added | K1: Original | L1: Original | M1: Original | N1: Original | O1: Original | P1: Added | Q1: Added | R1: Added | S1: Added | T1: Added | U1: Added | Y1: Added
A2: Decalog ID | B2: Yes or No | C2: Portfolios name | D2: Fund or Model | E2: On Original Risk List or Added by Ronan? | F2: On a List? | G2: Strategy Type | H2: Strategy Detail | I2: Macro Process | J2: Micro Process | K2: Investment team | L2: Portfolio Manager | M2: Family of Investment strategy | N2: Micro risk process name | O2: AuM in Audit File | P2: AUM from our AUM 30 April 2020 file | Q2: Ronan Comment | R2: Aum from Jun file Old | S2: Aum from Jun file | T2: Flows April | U2: AUM from our AUM 31st March 2020 file | V2: AUM from our AUM Feb 2020 file in mln * | W2: Difference | X2: Difference final | Y2: AUM from our AUM April 2020 file in mln* | Z2: Difference In AUM | AA2: Flows April mln | AB2: AUM from our AUM April 2020 file Test | AC2: AUM from our AUM Feb 2019 file Test | AD2: Difference Between Feb 2019 - April 2020
A3: E142 | B3: Yes | C3: AMUNDI FUND SOLUTIONS - BALANCED | D3: Fund | E3: On Original Risk List | F3: =VLOOKUP($A3,'[1]Dublin funds'!$B$2:$AS$153,2,FALSE) -> From Risk - Fund Responsibility - Dublin Funds | G3: =VLOOKUP($A3,'[2]Total AUM Data'!$A:$I,5,FALSE) -> Allocation Driven Strategies | H3: =VLOOKUP($A3,'[2]Total AUM Data'!$A:$I,6,FALSE) -> Moderate | I3: =VLOOKUP($A3,'[1]Dublin funds'!$B$2:$AS$153,3,FALSE) -> BAL Multimanagement | J3: =VLOOKUP($A3,'[1]Dublin funds'!$B$2:$AS$153,4,FALSE) -> DUB BAL Multimanagement SDA Fds de Fds | K3: AMUNDI.IRL/INV/MAS | L3: O'TOOLE JOHN | M3: Global - Global Balanced 50 | N3: DUB BAL Multimanagement SDA Fds de Fds | O3: =VLOOKUP(A3,'Audit AUM File'!A:B,2,FALSE) -> 1.7612646e+08 | P3: =VLOOKUP(A3,[3]AUM!$A$3:$B$131,2,0) -> 3.2400944e+08 | R3: =+IF(D3="",VLOOKUP(A3,'[2]Pivot for Jun AUM'!$A$5:$B$121,2,FALSE)) -> FALSE | S3: =+IF(D3<>"",VLOOKUP(A3,'[2]Total AUM Data'!$A$2:$G$48,7,FALSE)) -> 1.6934677e+08 | T3: =VLOOKUP(A3,[4]Flows!$A$3:$D$1206,4,0) -> -4401543.4 | U3: =VLOOKUP(A3,'[3]Last Aum File'!$A$2:$B$128,2,0) -> 3.2315034e+08 | V3: =+U3/1000000 -> 323.15034 | W3: =+IF(OR(A3="HF11",A3="PACIFAI"),0,IF(A3="MUSG",P3-U3/2,P3-U3)) -> 859094.12 | X3: =+IF(ISNA(W3),0,W3) -> 859094.12 | Y3: =P3/1000000 -> 324.00944 | Z3: =X3/1000000 -> 0.85909412 | AA3: =T3/1000000 -> -4.4015434 | AB3: =VLOOKUP(A3,[3]AUM!$A$3:$B$131,2,0)/1000000 -> 324.00944 | AC3: =VLOOKUP(A3,'[3]Last Aum File'!$A$2:$B$126,2,0)/1000000 -> 323.15034 | AD3: =AB3-AC3 -> 0.85909412
A4: E143 | B4: Yes | C4: AMUNDI FUND SOLUTIONS - CONSERVATIVE | D4: Fund | E4: On Original Risk List | F4: =VLOOKUP(A4,'[1]Dublin funds'!$B$2:$AS$153,2,FALSE) -> From Risk - Fund Responsibility - Dublin Funds | G4: =VLOOKUP($A4,'[2]Total AUM Data'!$A:$I,5,FALSE) -> Allocation Driven Strategies | H4: =VLOOKUP($A4,'[2]Total AUM Data'!$A:$I,6,FALSE) -> Conservative | I4: =VLOOKUP($A4,'[1]Dublin funds'!$B$2:$AS$153,3,FALSE) -> BAL Multimanagement | J4: =VLOOKUP($A4,'[1]Dublin funds'!$B$2:$AS$153,4,FALSE) -> DUB BAL Multimanagement SDA Fds de Fds | K4: AMUNDI.IRL/INV/MAS | L4: O'TOOLE JOHN | M4: Global - Balanced Global Defensive 20 | N4: DUB BAL Multimanagement SDA Fds de Fds | O4: =VLOOKUP(A4,'Audit AUM File'!A:B,2,FALSE) -> 2.0056959e+08 | P4: =VLOOKUP(A4,[3]AUM!$A$3:$B$131,2,0) -> 2.428063e+08 | R4: =+IF(D4="",VLOOKUP(A4,'[2]Pivot for Jun AUM'!$A$5:$B$121,2,FALSE)) -> FALSE | S4: =+IF(D4<>"",VLOOKUP(A4,'[2]Total AUM Data'!$A$2:$G$48,7,FALSE)) -> 1.9155414e+08 | T4: =VLOOKUP(A4,[4]Flows!$A$3:$D$1206,4,0) -> -6585274.1 | U4: =VLOOKUP(A4,'[3]Last Aum File'!$A$2:$B$128,2,0) -> 2.471471e+08 | V4: =+U4/1000000 -> 247.1471 | W4: =+IF(OR(A4="HF11",A4="PACIFAI"),0,IF(A4="MUSG",P4-U4/2,P4-U4)) -> -4340796.9 | X4: =+IF(ISNA(W4),0,W4) -> -4340796.9 | Y4: =P4/1000000 -> 242.8063 | Z4: =X4/1000000 -> -4.3407969 | AA4: =T4/1000000 -> -6.5852741 | AB4: =VLOOKUP(A4,[3]AUM!$A$3:$B$131,2,0)/1000000 -> 242.8063 | AC4: =VLOOKUP(A4,'[3]Last Aum File'!$A$2:$B$126,2,0)/1000000 -> 247.1471 | AD4: =AB4-AC4 -> -4.3407969
A5: E144 | B5: Yes | C5: AMUNDI FUND SOLUTIONS - DIVERSIFIED GROWTH - A | D5: Fund | E5: On Original Risk List | F5: =VLOOKUP(A5,'[1]Dublin funds'!$B$2:$AS$153,2,FALSE) -> From Risk - Fund Responsibility - Dublin Funds | G5: =VLOOKUP($A5,'[2]Total AUM Data'!$A:$I,5,FALSE) -> Allocation Driven Strategies | H5: =VLOOKUP($A5,'[2]Total AUM Data'!$A:$I,6,FALSE) -> Growth | I5: =VLOOKUP($A5,'[1]Dublin funds'!$B$2:$AS$153,3,FALSE) -> BAL Multimanagement | J5: =VLOOKUP($A5,'[1]Dublin funds'!$B$2:$AS$153,4,FALSE) -> AMU BAL SDA Fds de Fds (used some absolute limits with High Rik with Equity exposure 0/120% and currency exposure up to 100% | K5: AMUNDI.IRL/INV/MAS | L5: O'TOOLE JOHN | M5: Multi Asset - Diversified Growth | N5: DUB BAL Multimanagement SDA Fds de Fds | O5: =VLOOKUP(A5,'Audit AUM File'!A:B,2,FALSE) -> 68345862 | P5: =VLOOKUP(A5,[3]AUM!$A$3:$B$131,2,0) -> 83823204 | R5: =+IF(D5="",VLOOKUP(A5,'[2]Pivot for Jun AUM'!$A$5:$B$121,2,FALSE)) -> FALSE | S5: =+IF(D5<>"",VLOOKUP(A5,'[2]Total AUM Data'!$A$2:$G$48,7,FALSE)) -> 66139609 | T5: =VLOOKUP(A5,[4]Flows!$A$3:$D$1206,4,0) -> -1199812.8 | U5: =VLOOKUP(A5,'[3]Last Aum File'!$A$2:$B$128,2,0) -> 85685109 | V5: =+U5/1000000 -> 85.685109 | W5: =+IF(OR(A5="HF11",A5="PACIFAI"),0,IF(A5="MUSG",P5-U5/2,P5-U5)) -> -1861905.1 | X5: =+IF(ISNA(W5),0,W5) -> -1861905.1 | Y5: =P5/1000000 -> 83.823204 | Z5: =X5/1000000 -> -1.8619051 | AA5: =T5/1000000 -> -1.1998128 | AB5: =VLOOKUP(A5,[3]AUM!$A$3:$B$131,2,0)/1000000 -> 83.823204 | AC5: =VLOOKUP(A5,'[3]Last Aum File'!$A$2:$B$126,2,0)/1000000 -> 85.685109 | AD5: =AB5-AC5 -> -1.8619051
A6: PF101376 | B6: Yes | C6: AFS ICAV Planet ESG Balanced | D6: Fund | E6: On Original Risk List | F6: From Risk - Fund Responsibility - Dublin Funds | G6: Allocation Driven Strategies | H6: Moderate | I6: BAL Multimanagement | J6: DUB BAL Multimanagement SDA Fds de Fds | K6: AMUNDI.IRL/INV/MAS | L6: O'TOOLE JOHN | M6: Global - Global Balanced 50 | N6: DUB BAL Multimanagement SDA Fds de Fds | R6: =+IF(D6="",VLOOKUP(A6,'[2]Pivot for Jun AUM'!$A$5:$B$121,2,FALSE)) -> FALSE
A7: PF101372 | B7: Yes | C7: AFS ICAV Planet ESG Conservative | D7: Fund | E7: On Original Risk List | F7: From Risk - Fund Responsibility - Dublin Funds | G7: Allocation Driven Strategies | H7: Conservative | I7: BAL Multimanagement | J7: DUB BAL Multimanagement SDA Fds de Fds | K7: AMUNDI.IRL/INV/MAS | L7: O'TOOLE JOHN | M7: Global - Balanced Global Defensive 20 | N7: DUB BAL Multimanagement SDA Fds de Fds | R7: =+IF(D7="",VLOOKUP(A7,'[2]Pivot for Jun AUM'!$A$5:$B$121,2,FALSE)) -> FALSE
A8: PF101380 | B8: Yes | C8: AFS ICAV Planet ESG Dynamic | D8: Fund | E8: On Original Risk List | F8: From Risk - Fund Responsibility - Dublin Funds | G8: Allocation Driven Strategies | H8: Growth | I8: BAL Multimanagement | J8: AMU BAL SDA Fds de Fds (used some absolute limits with High Rik with Equity exposure 0/120% and currency exposure up to 100% | K8: AMUNDI.IRL/INV/MAS | L8: O'TOOLE JOHN | M8: Multi Asset - Diversified Growth | N8: DUB BAL Multimanagement SDA Fds de Fds | R8: =+IF(D8="",VLOOKUP(A8,'[2]Pivot for Jun AUM'!$A$5:$B$121,2,FALSE)) -> FALSE
A9: PF78195 | B9: Yes | C9: AMUNDI SOLUZIONI ITALIA - PROGETTO AZIONE CAMBIAMENTO CLIMATICO - E | D9: Fund | E9: On Original Risk List | F9: =VLOOKUP(A9,'[1]Dublin funds'!$B$2:$AS$153,2,FALSE) -> From Risk - Fund Responsibility - Dublin Funds | G9: =VLOOKUP($A9,'[2]Total AUM Data'!$A:$I,5,FALSE) -> Outcome Oriented Strategies | H9: =VLOOKUP($A9,'[2]Total AUM Data'!$A:$I,6,FALSE) -> Risk Accumulation | I9: =VLOOKUP($A9,'[1]Dublin funds'!$B$2:$AS$153,3,FALSE) -> EFI Absolute Return | J9: =VLOOKUP($A9,'[1]Dublin funds'!$B$2:$AS$153,4,FALSE) -> DUB EFI Absolute Return Aggregate | K9: AMUNDI.IRL/INV/MAS | L9: O'TOOLE JOHN | M9: To be Affected | N9: DUB EFI Absolute Return Aggregate | O9: =VLOOKUP(A9,'Audit AUM File'!A:B,2,FALSE) -> 3.362137e+08 | R9: =+IF(D9="",VLOOKUP(A9,'[2]Pivot for Jun AUM'!$A$5:$B$121,2,FALSE)) -> FALSE | S9: =+IF(D9<>"",VLOOKUP(A9,'[2]Total AUM Data'!$A$2:$G$48,7,FALSE)) -> 3.3503735e+08
A10: PF103025 | B10: Yes | C10: ASI - PROGETTO AZIONE FUTURO GREEN | D10: Fund | E10: On Original Risk List | F10: From Risk - Fund Responsibility - Dublin Funds | G10: Outcome Oriented Strategies | H10: Risk Accumulation | K10: AMUNDI.IRL/INV/MAS/PMG/PMG | L10: CASEY RICHARD | M10: To be Affected | P10: =VLOOKUP(A10,[3]AUM!$A$3:$B$131,2,0) -> 93538758 | T10: =VLOOKUP(A10,[4]Flows!$A$3:$D$1206,4,0) -> -18151357 | U10: =VLOOKUP(A10,'[3]Last Aum File'!$A$2:$B$128,2,0) -> 1.1168e+08 | V10: =+U10/1000000 -> 111.68 | W10: =+IF(OR(A10="HF11",A10="PACIFAI"),0,IF(A10="MUSG",P10-U10/2,P10-U10)) -> -18141244 | X10: =+IF(ISNA(W10),0,W10) -> -18141244 | Y10: =P10/1000000 -> 93.538758 | Z10: =X10/1000000 -> -18.141244 | AA10: =T10/1000000 -> -18.151357 | AB10: =VLOOKUP(A10,[3]AUM!$A$3:$B$131,2,0)/1000000 -> 93.538758
A11: E118 | B11: Yes | C11: AMUNDI UNICREDIT PREM PORT- PRUDENTIAL | D11: Fund | E11: On Original Risk List | F11: =VLOOKUP(A11,'[1]Dublin funds'!$B$2:$AS$153,2,FALSE) -> From Risk - Fund Responsibility - Dublin Funds | G11: =VLOOKUP($A11,'[2]Total AUM Data'!$A:$I,5,FALSE) -> Allocation Driven Strategies | H11: =VLOOKUP($A11,'[2]Total AUM Data'!$A:$I,6,FALSE) -> Conservative | I11: =VLOOKUP($A11,'[1]Dublin funds'!$B$2:$AS$153,3,FALSE) -> BAL Multimanagement | J11: =VLOOKUP($A11,'[1]Dublin funds'!$B$2:$AS$153,4,FALSE) -> DUB BAL Multimanagement SDA Fds de Fds | K11: AMUNDI.IRL/INV/MAS | L11: O'TOOLE JOHN | M11: Bond - myNext | N11: DUB BAL Multimanagement SDA Fds de Fds | O11: =VLOOKUP(A11,'Audit AUM File'!A:B,2,FALSE) -> 31835018 | P11: =VLOOKUP(A11,[3]AUM!$A$3:$B$131,2,0) -> 7495265.8 | R11: =+IF(D11="",VLOOKUP(A11,'[2]Pivot for Jun AUM'!$A$5:$B$121,2,FALSE)) -> FALSE | S11: =+IF(D11<>"",VLOOKUP(A11,'[2]Total AUM Data'!$A$2:$G$48,7,FALSE)) -> 33826169 | T11: =VLOOKUP(A11,[4]Flows!$A$3:$D$1206,4,0) -> -798922.58 | U11: =VLOOKUP(A11,'[3]Last Aum File'!$A$2:$B$128,2,0) -> 8321680 | V11: =+U11/1000000 -> 8.32168 | W11: =+IF(OR(A11="HF11",A11="PACIFAI"),0,IF(A11="MUSG",P11-U11/2,P11-U11)) -> -826414.19 | X11: =+IF(ISNA(W11),0,W11) -> -826414.19 | Y11: =P11/1000000 -> 7.4952658 | Z11: =X11/1000000 -> -0.82641419 | AA11: =T11/1000000 -> -0.79892258 | AB11: =VLOOKUP(A11,[3]AUM!$A$3:$B$131,2,0)/1000000 -> 7.4952658 | AC11: =VLOOKUP(A11,'[3]Last Aum File'!$A$2:$B$126,2,0)/1000000 -> 8.32168 | AD11: =AB11-AC11 -> -0.82641419
A12: E119 | B12: Yes | C12: AMUNDI UNICREDIT PREMIUM PORT - DYNAMIC | D12: Fund | E12: On Original Risk List | F12: =VLOOKUP(A12,'[1]Dublin funds'!$B$2:$AS$153,2,FALSE) -> From Risk - Fund Responsibility - Dublin Funds | G12: =VLOOKUP($A12,'[2]Total AUM Data'!$A:$I,5,FALSE) -> Allocation Driven Strategies | H12: =VLOOKUP($A12,'[2]Total AUM Data'!$A:$I,6,FALSE) -> Growth | I12: =VLOOKUP($A12,'[1]Dublin funds'!$B$2:$AS$153,3,FALSE) -> BAL Multimanagement | J12: =VLOOKUP($A12,'[1]Dublin funds'!$B$2:$AS$153,4,FALSE) -> DUB BAL Multimanagement SDA Fds de Fds | K12: AMUNDI.IRL/INV/MAS | L12: O'TOOLE JOHN | M12: Equity - myNext | N12: DUB BAL Multimanagement SDA Fds de Fds | O12: =VLOOKUP(A12,'Audit AUM File'!A:B,2,FALSE) -> 96972832 | P12: =VLOOKUP(A12,[3]AUM!$A$3:$B$131,2,0) -> 58236487 | R12: =+IF(D12="",VLOOKUP(A12,'[2]Pivot for Jun AUM'!$A$5:$B$121,2,FALSE)) -> FALSE | S12: =+IF(D12<>"",VLOOKUP(A12,'[2]Total AUM Data'!$A$2:$G$48,7,FALSE)) -> 1.0325593e+08 | T12: =VLOOKUP(A12,[4]Flows!$A$3:$D$1206,4,0) -> -1656568.1 | U12: =VLOOKUP(A12,'[3]Last Aum File'!$A$2:$B$128,2,0) -> 56591526 | V12: =+U12/1000000 -> 56.591526 | W12: =+IF(OR(A12="HF11",A12="PACIFAI"),0,IF(A12="MUSG",P12-U12/2,P12-U12)) -> 1644961.7 | X12: =+IF(ISNA(W12),0,W12) -> 1644961.7 | Y12: =P12/1000000 -> 58.236487 | Z12: =X12/1000000 -> 1.6449617 | AA12: =T12/1000000 -> -1.6565681 | AB12: =VLOOKUP(A12,[3]AUM!$A$3:$B$131,2,0)/1000000 -> 58.236487 | AC12: =VLOOKUP(A12,'[3]Last Aum File'!$A$2:$B$126,2,0)/1000000 -> 56.591526 | AD12: =AB12-AC12 -> 1.6449617
A13: E120 | B13: Yes | C13: AMUNDI UNICREDIT PREM PORT- MULTI ASSET | D13: Fund | E13: On Original Risk List | F13: =VLOOKUP(A13,'[1]Dublin funds'!$B$2:$AS$153,2,FALSE) -> From Risk - Fund Responsibility - Dublin Funds | G13: =VLOOKUP($A13,'[2]Total AUM Data'!$A:$I,5,FALSE) -> Allocation Driven Strategies | H13: =VLOOKUP($A13,'[2]Total AUM Data'!$A:$I,6,FALSE) -> Moderate | I13: =VLOOKUP($A13,'[1]Dublin funds'!$B$2:$AS$153,3,FALSE) -> BAL Multimanagement | J13: =VLOOKUP($A13,'[1]Dublin funds'!$B$2:$AS$153,4,FALSE) -> DUB BAL Multimanagement SDA Fds de Fds | K13: AMUNDI.IRL/INV/MAS | L13: O'TOOLE JOHN | M13: Multi Asset - myNext | N13: DUB BAL Multimanagement SDA Fds de Fds | O13: =VLOOKUP(A13,'Audit AUM File'!A:B,2,FALSE) -> 2.8861759e+08 | P13: =VLOOKUP(A13,[3]AUM!$A$3:$B$131,2,0) -> 1.2144878e+08 | R13: =+IF(D13="",VLOOKUP(A13,'[2]Pivot for Jun AUM'!$A$5:$B$121,2,FALSE)) -> FALSE | S13: =+IF(D13<>"",VLOOKUP(A13,'[2]Total AUM Data'!$A$2:$G$48,7,FALSE)) -> 3.124575e+08 | T13: =VLOOKUP(A13,[4]Flows!$A$3:$D$1206,4,0) -> -5424835.6 | U13: =VLOOKUP(A13,'[3]Last Aum File'!$A$2:$B$128,2,0) -> 1.2393751e+08 | V13: =+U13/1000000 -> 123.93751 | W13: =+IF(OR(A13="HF11",A13="PACIFAI"),0,IF(A13="MUSG",P13-U13/2,P13-U13)) -> -2488723.7 | X13: =+IF(ISNA(W13),0,W13) -> -2488723.7 | Y13: =P13/1000000 -> 121.44878 | Z13: =X13/1000000 -> -2.4887237 | AA13: =T13/1000000 -> -5.4248356 | AB13: =VLOOKUP(A13,[3]AUM!$A$3:$B$131,2,0)/1000000 -> 121.44878 | AC13: =VLOOKUP(A13,'[3]Last Aum File'!$A$2:$B$126,2,0)/1000000 -> 123.93751 | AD13: =AB13-AC13 -> -2.4887237
A14: PF115036 | C14: THE TRUSTHOUSE FDN CPI+4% MULTI-AST PTF | D14: Fund | G14: Outcome Oriented Strategies | H14: Income | P14: =VLOOKUP(A14,[3]AUM!$A$3:$B$131,2,0) -> 98145265 | T14: =VLOOKUP(A14,[4]Flows!$A$3:$D$1206,4,0) -> 0 | U14: =VLOOKUP(A14,'[3]Last Aum File'!$A$2:$B$1262,2,0) -> 98124607 | V14: =+U14/1000000 -> 98.124607 | W14: =+IF(OR(A14="HF11",A14="PACIFAI"),0,IF(A14="MUSG",P14-U14/2,P14-U14)) -> 20657.66 | X14: =+IF(ISNA(W14),0,W14) -> 20657.66 | Y14: =P14/1000000 -> 98.145265 | Z14: =X14/1000000 -> 0.02065766 | AA14: =T14/1000000 -> 0 | AB14: =VLOOKUP(A14,[3]AUM!$A$3:$B$131,2,0)/1000000 -> 98.145265 | AC14: =VLOOKUP(A14,'[3]Last Aum File'!$A$2:$B$126,2,0)/1000000 -> 98.124607 | AD14: =AB14-AC14 -> 0.02065766
A15: PF204806 | C15: AMUNDI-FUNDACION CAJA NAVARRA DYNAMIC | D15: Fund | G15: Allocation Driven Strategies | H15: Growth | P15: =VLOOKUP(A15,[3]AUM!$A$3:$B$131,2,0) -> 27952778 | T15: =P15 -> 27952778 | V15: =+U15/1000000 -> 0 | W15: =+IF(OR(A15="HF11",A15="PACIFAI"),0,IF(A15="MUSG",P15-U15/2,P15-U15)) -> 27952778 | X15: =+IF(ISNA(W15),0,W15) -> 27952778 | Y15: =P15/1000000 -> 27.952778 | Z15: =X15/1000000 -> 27.952778 | AA15: =T15/1000000 -> 27.952778 | AB15: =VLOOKUP(A15,[3]AUM!$A$3:$B$131,2,0)/1000000 -> 27.952778 | AD15: =AB15-AC15 -> 27.952778
A16: PF88524 | B16: Yes | C16: AMUNDI ELITE THEMATIC MULTI ASSET | D16: Fund | E16: On Original Risk List | F16: From Risk - Fund Responsibility - Dublin Funds | G16: Outcome Oriented Strategies | H16: Thematic | I16: BAL Multimanagement | J16: AMU BAL SDA Fds de Fds (used absolute limits High risk) | K16: AMUNDI.IRL/INV/MAS | L16: O'TOOLE JOHN | M16: AMUNDI ELITE THEMATIC MULTI ASSET | N16: DUB BAL Multimanagement SDA Fds de Fds | P16: =VLOOKUP(A16,[3]AUM!$A$3:$B$131,2,0) -> 6.5152609e+08 | R16: =+IF(D16="",VLOOKUP(A16,'[2]Pivot for Jun AUM'!$A$5:$B$121,2,FALSE)) -> FALSE | T16: =VLOOKUP(A16,[4]Flows!$A$3:$D$1206,4,0) -> -1.3691224e+08 | U16: =VLOOKUP(A16,'[3]Last Aum File'!$A$2:$B$128,2,0) -> 5.3284487e+08 | V16: =+U16/1000000 -> 532.84487 | W16: =+IF(OR(A16="HF11",A16="PACIFAI"),0,IF(A16="MUSG",P16-U16/2,P16-U16)) -> 1.1868122e+08 | X16: =+IF(ISNA(W16),0,W16) -> 1.1868122e+08 | Y16: =P16/1000000 -> 651.52609 | Z16: =X16/1000000 -> 118.68122 | AA16: =T16/1000000 -> -136.91224 | AB16: =VLOOKUP(A16,[3]AUM!$A$3:$B$131,2,0)/1000000 -> 651.52609 | AC16: =VLOOKUP(A16,'[3]Last Aum File'!$A$2:$B$126,2,0)/1000000 -> 532.84487 | AD16: =AB16-AC16 -> 118.68122
A17: E209 | B17: Yes | C17: PI INVESTMENT FUNDS - DYNAMIC ALLOCATION FUND - E | D17: Fund | E17: On Original Risk List | F17: =VLOOKUP(A17,'[1]Dublin funds'!$B$2:$AS$153,2,FALSE) -> From Risk - Fund Responsibility - Dublin Funds | G17: =VLOOKUP($A17,'[2]Total AUM Data'!$A:$I,5,FALSE) -> Service Fund | H17: =VLOOKUP($A17,'[2]Total AUM Data'!$A:$I,6,FALSE) -> Flexible | I17: =VLOOKUP($A17,'[1]Dublin funds'!$B$2:$AS$153,3,FALSE) -> TBD | J17: =VLOOKUP($A17,'[1]Dublin funds'!$B$2:$AS$153,4,FALSE) -> Agreed a light touch with VaR and Leverage limits | K17: AMUNDI.IRL/INV/MAS/PMG | L17: BUONO SALVATORE | M17: To be Affected | N17: To Be Determined | O17: =VLOOKUP(A17,'Audit AUM File'!A:B,2,FALSE) -> 6.2364273e+08 | P17: =VLOOKUP(A17,[3]AUM!$A$3:$B$131,2,0) -> 1.987592e+08 | R17: =+IF(D17="",VLOOKUP(A17,'[2]Pivot for Jun AUM'!$A$5:$B$121,2,FALSE)) -> FALSE | S17: =+IF(D17<>"",VLOOKUP(A17,'[2]Total AUM Data'!$A$2:$G$48,7,FALSE)) -> 4.0254202e+08 | T17: =VLOOKUP(A17,[4]Flows!$A$3:$D$1206,4,0) -> -26306785 | U17: =VLOOKUP(A17,'[3]Last Aum File'!$A$2:$B$128,2,0) -> 2.3421407e+08 | V17: =+U17/1000000 -> 234.21407 | W17: =+IF(OR(A17="HF11",A17="PACIFAI"),0,IF(A17="MUSG",P17-U17/2,P17-U17)) -> -35454872 | X17: =+IF(ISNA(W17),0,W17) -> -35454872 | Y17: =P17/1000000 -> 198.7592 | Z17: =X17/1000000 -> -35.454872 | AA17: =T17/1000000 -> -26.306785 | AB17: =VLOOKUP(A17,[3]AUM!$A$3:$B$131,2,0)/1000000 -> 198.7592 | AC17: =VLOOKUP(A17,'[3]Last Aum File'!$A$2:$B$126,2,0)/1000000 -> 234.21407 | AD17: =AB17-AC17 -> -35.454872
A18: PF87100 | B18: Yes | C18: AMUNDI FUND SOLUTIONS - SABADELL URQUIJO ACUMULACION | D18: Fund | E18: On Original Risk List | F18: From Risk - Fund Responsibility - Dublin Funds | G18: Allocation Driven Strategies | H18: Conservative | I18: BAL Multimanagement | J18: DUB BAL Multimanagement SDA Fds de Fds | K18: AMUNDI.IRL/INV/MAS | L18: O'TOOLE JOHN | M18: Global - Balanced Global Defensive 20 | N18: DUB BAL Multimanagement SDA Fds de Fds | P18: =VLOOKUP(A18,[3]AUM!$A$3:$B$131,2,0) -> 6970226.2 | R18: =+IF(D18="",VLOOKUP(A18,'[2]Pivot for Jun AUM'!$A$5:$B$121,2,FALSE)) -> FALSE | T18: =VLOOKUP(A18,[4]Flows!$A$3:$D$1206,4,0) -> 0 | U18: =VLOOKUP(A18,'[3]Last Aum File'!$A$2:$B$128,2,0) -> 6970226.2 | V18: =+U18/1000000 -> 6.9702262 | W18: =+IF(OR(A18="HF11",A18="PACIFAI"),0,IF(A18="MUSG",P18-U18/2,P18-U18)) -> 0 | X18: =+IF(ISNA(W18),0,W18) -> 0 | Y18: =P18/1000000 -> 6.9702262 | Z18: =X18/1000000 -> 0 | AA18: =T18/1000000 -> 0 | AB18: =VLOOKUP(A18,[3]AUM!$A$3:$B$131,2,0)/1000000 -> 6.9702262 | AC18: =VLOOKUP(A18,'[3]Last Aum File'!$A$2:$B$126,2,0)/1000000 -> 6.9702262 | AD18: =AB18-AC18 -> 0
A19: PF87115 | B19: Yes | C19: AMUNDI FUND SOLUTIONS - SABADELL URQUIJO CRECIMIENTO | D19: Fund | E19: On Original Risk List | F19: From Risk - Fund Responsibility - Dublin Funds | G19: Allocation Driven Strategies | H19: Growth | I19: BAL Multimanagement | J19: AMU BAL SDA Fds de Fds (used some absolute limits with High Rik with Equity exposure 0/120% and currency exposure up to 100% | K19: AMUNDI.IRL/INV/MAS | L19: O'TOOLE JOHN | M19: Multi Asset - Diversified Growth | N19: DUB BAL Multimanagement SDA Fds de Fds | P19: =VLOOKUP(A19,[3]AUM!$A$3:$B$131,2,0) -> 3927561.1 | R19: =+IF(D19="",VLOOKUP(A19,'[2]Pivot for Jun AUM'!$A$5:$B$121,2,FALSE)) -> FALSE | T19: =VLOOKUP(A19,[4]Flows!$A$3:$D$1206,4,0) -> 0 | U19: =VLOOKUP(A19,'[3]Last Aum File'!$A$2:$B$128,2,0) -> 3927561.1 | V19: =+U19/1000000 -> 3.9275611 | W19: =+IF(OR(A19="HF11",A19="PACIFAI"),0,IF(A19="MUSG",P19-U19/2,P19-U19)) -> 0 | X19: =+IF(ISNA(W19),0,W19) -> 0 | Y19: =P19/1000000 -> 3.9275611 | Z19: =X19/1000000 -> 0 | AA19: =T19/1000000 -> 0 | AB19: =VLOOKUP(A19,[3]AUM!$A$3:$B$131,2,0)/1000000 -> 3.9275611 | AC19: =VLOOKUP(A19,'[3]Last Aum File'!$A$2:$B$126,2,0)/1000000 -> 3.9275611 | AD19: =AB19-AC19 -> 0
A20: PF92127 | B20: Yes | C20: AMUNDI SOLUZIONI ITALIA - PROGETTO AZIONE INFRASTRUTTURE SOSTENIBILI | D20: Fund | E20: On Original Risk List | F20: From Risk - Fund Responsibility - Dublin Funds | G20: Outcome Oriented Strategies | H20: Risk Accumulation | I20: 0 | J20: 0 | K20: AMUNDI.IRL/INV/MAS/PMG/PMG | L20: CASEY RICHARD | M20: To be Affected | N20: DUB EFI Absolute Return Aggregate | P20: =VLOOKUP(A20,[3]AUM!$A$3:$B$131,2,0) -> 3.3514686e+08 | R20: =+IF(D20="",VLOOKUP(A20,'[2]Pivot for Jun AUM'!$A$5:$B$121,2,FALSE)) -> FALSE | T20: =VLOOKUP(A20,[4]Flows!$A$3:$D$1206,4,0) -> -1.1498841e+08 | U20: =VLOOKUP(A20,'[3]Last Aum File'!$A$2:$B$128,2,0) -> 4.7382049e+08 | V20: =+U20/1000000 -> 473.82049 | W20: =+IF(OR(A20="HF11",A20="PACIFAI"),0,IF(A20="MUSG",P20-U20/2,P20-U20)) -> -1.3867363e+08 | X20: =+IF(ISNA(W20),0,W20) -> -1.3867363e+08 | Y20: =P20/1000000 -> 335.14686 | Z20: =X20/1000000 -> -138.67363 | AA20: =T20/1000000 -> -114.98841 | AB20: =VLOOKUP(A20,[3]AUM!$A$3:$B$131,2,0)/1000000 -> 335.14686 | AC20: =VLOOKUP(A20,'[3]Last Aum File'!$A$2:$B$126,2,0)/1000000 -> 473.82049 | AD20: =AB20-AC20 -> -138.67363
A21: PF95239 | B21: Yes | C21: AMUNDI SOLUZIONI ITALIA - PROGETTO AZIONE INFRASTRUTTURE SOSTENIBILI (II) | D21: Fund | E21: On Original Risk List | F21: From Risk - Fund Responsibility - Dublin Funds | G21: Outcome Oriented Strategies | H21: Risk Accumulation | I21: 0 | J21: 0 | K21: AMUNDI.IRL/INV/MAS/PMG/PMG | L21: CASEY RICHARD | M21: To be Affected | N21: DUB EFI Absolute Return Aggregate | P21: =VLOOKUP(A21,[3]AUM!$A$3:$B$131,2,0) -> 3.1941249e+08 | R21: =+IF(D21="",VLOOKUP(A21,'[2]Pivot for Jun AUM'!$A$5:$B$121,2,FALSE)) -> FALSE | T21: =VLOOKUP(A21,[4]Flows!$A$3:$D$1206,4,0) -> -68314788 | U21: =VLOOKUP(A21,'[3]Last Aum File'!$A$2:$B$128,2,0) -> 4.0863579e+08 | V21: =+U21/1000000 -> 408.63579 | W21: =+IF(OR(A21="HF11",A21="PACIFAI"),0,IF(A21="MUSG",P21-U21/2,P21-U21)) -> -89223301 | X21: =+IF(ISNA(W21),0,W21) -> -89223301 | Y21: =P21/1000000 -> 319.41249 | Z21: =X21/1000000 -> -89.223301 | AA21: =T21/1000000 -> -68.314788 | AB21: =VLOOKUP(A21,[3]AUM!$A$3:$B$131,2,0)/1000000 -> 319.41249 | AC21: =VLOOKUP(A21,'[3]Last Aum File'!$A$2:$B$126,2,0)/1000000 -> 408.63579 | AD21: =AB21-AC21 -> -89.223301
A22: PF201311 | B22: Yes | C22: AMUNDI SENTIERO SOSTENIBILE | D22: Fund | E22: On Original Risk List | F22: From Risk - Fund Responsibility - Dublin Funds | G22: Outcome Oriented Strategies | H22: Risk Accumulation | I22: 0 | J22: 0 | K22: AMUNDI.IRL/INV/MAS/PMG/PMG | L22: CASEY RICHARD | M22: To be Affected | N22: DUB EFI Absolute Return Aggregate | P22: =VLOOKUP(A22,[3]AUM!$A$3:$B$131,2,0) -> 2.9032318e+08 | R22: =+IF(D22="",VLOOKUP(A22,'[2]Pivot for Jun AUM'!$A$5:$B$121,2,FALSE)) -> FALSE | T22: -10126505 | U22: 2.9765464e+08 | V22: =+U22/1000000 -> 297.65464 | W22: =+IF(OR(A22="HF11",A22="PACIFAI"),0,IF(A22="MUSG",P22-U22/2,P22-U22)) -> -7331455.9 | X22: =+IF(ISNA(W22),0,W22) -> -7331455.9 | Y22: =P22/1000000 -> 290.32318 | Z22: =X22/1000000 -> -7.3314559 | AA22: =T22/1000000 -> -10.126505 | AB22: =VLOOKUP(A22,[3]AUM!$A$3:$B$131,2,0)/1000000 -> 290.32318 | AC22: =VLOOKUP(A22,'[3]Last Aum File'!$A$2:$B$126,2,0)/1000000 -> 291.99146 | AD22: =AB22-AC22 -> -1.6682759
A23: SAXO | B23: Yes | C23: SAXO EUROPE | D23: Model | E23: On Original Risk List | F23: From Risk - Fund Responsibility - Dublin Funds | G23: Allocation Driven Strategies | H23: Conservative | I23: BAL Multimanagement | J23: DUB BAL Multimanagement Alt Greenway | K23: AMUNDI.IRL/INV/MAS/PMG/PMG | L23: Jen | M23: To be Affected | N23: DUB BAL Multimanagement Alt Greenway | P23: 1.9219966e+08 | R23: FALSE | S23: 0 | T23: =P23-U23 -> -7061169.1 | U23: 1.9926083e+08 | V23: =+U23/1000000 -> 199.26083 | W23: =+IF(OR(A23="HF11",A23="PACIFAI"),0,IF(A23="MUSG",P23-U23/2,P23-U23)) -> -7061169.1 | X23: =+IF(ISNA(W23),0,W23) -> -7061169.1 | Y23: =P23/1000000 -> 192.19966 | Z23: =X23/1000000 -> -7.0611691 | AA23: =T23/1000000 -> -7.0611691 | AD23: =AB23-AC23 -> 0
A25: PSUKLD1 | B25: Yes | C25: Amundi Invensys Broad Bond Portfolio | D25: Fund | E25: On Original Risk List | F25: =VLOOKUP(A25,'[1]Dublin funds'!$B$2:$AS$153,2,FALSE) -> From Risk - Fund Responsibility - Dublin Funds | G25: =VLOOKUP($A25,'[2]Total AUM Data'!$A:$I,5,FALSE) -> Allocation Driven Strategies | H25: =VLOOKUP($A25,'[2]Total AUM Data'!$A:$I,6,FALSE) -> Flexible | I25: =VLOOKUP($A25,'[1]Dublin funds'!$B$2:$AS$153,3,FALSE) -> BAL Multimanagement | J25: =VLOOKUP($A25,'[1]Dublin funds'!$B$2:$AS$153,4,FALSE) -> AMU BAL SDA Fds de Fds (used some absolute limits with Low Rik) | K25: AMUNDI.IRL/INV/MAS/PMG/PMG | L25: CASEY RICHARD | M25: To be Affected | N25: DUB BAL Multimanagement SDA Fds de Fds | O25: =VLOOKUP(A25,'Audit AUM File'!A:B,2,FALSE) -> 0 | P25: =VLOOKUP(A25,[3]AUM!$A$3:$B$131,2,0)/0.8338 -> 1.6920099e+08 | R25: =+IF(D25="",VLOOKUP(A25,'[2]Pivot for Jun AUM'!$A$5:$B$121,2,FALSE)) -> FALSE | T25: =VLOOKUP(A25,[4]Flows!$A$3:$D$126,4,0) -> 0 | U25: =VLOOKUP(A25,'[3]Last Aum File'!$A$2:$B$128,2,0)/0.8338 -> 1.6577117e+08 | V25: =+U25/1000000 -> 165.77117 | W25: =+IF(OR(A25="HF11",A25="PACIFAI"),0,IF(A25="MUSG",P25-U25/2,P25-U25)) -> 3429821.8 | X25: =+IF(ISNA(W25),0,W25) -> 3429821.8 | Y25: =P25/1000000 -> 169.20099 | Z25: =X25/1000000 -> 3.4298218 | AA25: =T25/1000000 -> 0 | AB25: =VLOOKUP(A25,[3]AUM!$A$3:$B$131,2,0)/1000000 -> 141.07979 | AC25: =VLOOKUP(A25,'[3]Last Aum File'!$A$2:$B$126,2,0)/1000000 -> 138.22 | AD25: =AB25-AC25 -> 2.8597854
A26: PF79139 | B26: Yes | C26: AMUNDI SOLUZIONI ITALIA - PROGETTO AZIONE CAMBIAMENTO CLIMATICO (II) - E | D26: Fund | E26: On Original Risk List | F26: =VLOOKUP(A26,'[1]Dublin funds'!$B$2:$AS$153,2,FALSE) -> From Risk - Fund Responsibility - Dublin Funds | G26: =VLOOKUP($A26,'[2]Total AUM Data'!$A:$I,5,FALSE) -> Outcome Oriented Strategies | H26: =VLOOKUP($A26,'[2]Total AUM Data'!$A:$I,6,FALSE) -> Risk Accumulation | I26: =VLOOKUP($A26,'[1]Dublin funds'!$B$2:$AS$153,3,FALSE) -> 0 | J26: =VLOOKUP($A26,'[1]Dublin funds'!$B$2:$AS$153,4,FALSE) -> 0 | K26: AMUNDI.IRL/INV/MAS/PMG/PMG | L26: CASEY RICHARD | M26: To be Affected | N26: DUB EFI Absolute Return Aggregate | O26: =VLOOKUP(A26,'Audit AUM File'!A:B,2,FALSE) -> 1.4390381e+08 | Q26: Needs a Macro & Micro Process assigned? | R26: =+IF(D26="",VLOOKUP(A26,'[2]Pivot for Jun AUM'!$A$5:$B$121,2,FALSE)) -> FALSE | S26: =+IF(D26<>"",VLOOKUP(A26,'[2]Total AUM Data'!$A$2:$G$48,7,FALSE)) -> 59757670
A27: PF71664 | B27: Yes | C27: AMUNDI SOLUZIONI ITALIA - PROGETTO AZIONE MEGATREND - E | D27: Fund | E27: On Original Risk List | F27: =VLOOKUP(A27,'[1]Dublin funds'!$B$2:$AS$153,2,FALSE) -> From Risk - Fund Responsibility - Dublin Funds | G27: =VLOOKUP($A27,'[2]Total AUM Data'!$A:$I,5,FALSE) -> Outcome Oriented Strategies | H27: =VLOOKUP($A27,'[2]Total AUM Data'!$A:$I,6,FALSE) -> Risk Accumulation | I27: =VLOOKUP($A27,'[1]Dublin funds'!$B$2:$AS$153,3,FALSE) -> EFI Absolute Return | J27: =VLOOKUP($A27,'[1]Dublin funds'!$B$2:$AS$153,4,FALSE) -> DUB EFI Absolute Return Aggregate | K27: AMUNDI.IRL/INV/MAS/PMG/PMG | L27: CASEY RICHARD | M27: To be Affected | N27: DUB EFI Absolute Return Aggregate | O27: =VLOOKUP(A27,'Audit AUM File'!A:B,2,FALSE) -> 4.9375402e+08 | R27: =+IF(D27="",VLOOKUP(A27,'[2]Pivot for Jun AUM'!$A$5:$B$121,2,FALSE)) -> FALSE | S27: =+IF(D27<>"",VLOOKUP(A27,'[2]Total AUM Data'!$A$2:$G$48,7,FALSE)) -> 4.9380701e+08
A28: PF76580 | B28: Yes | C28: AMUNDI SOLUZIONI ITALIA - PROGETTO AZIONE MEGATREND (II) - E | D28: Fund | E28: On Original Risk List | F28: =VLOOKUP(A28,'[1]Dublin funds'!$B$2:$AS$153,2,FALSE) -> From Risk - Fund Responsibility - Dublin Funds | G28: =VLOOKUP($A28,'[2]Total AUM Data'!$A:$I,5,FALSE) -> Outcome Oriented Strategies | H28: =VLOOKUP($A28,'[2]Total AUM Data'!$A:$I,6,FALSE) -> Risk Accumulation | I28: =VLOOKUP($A28,'[1]Dublin funds'!$B$2:$AS$153,3,FALSE) -> EFI Absolute Return | J28: =VLOOKUP($A28,'[1]Dublin funds'!$B$2:$AS$153,4,FALSE) -> DUB EFI Absolute Return Aggregate | K28: AMUNDI.IRL/INV/MAS/PMG/PMG | L28: CASEY RICHARD | M28: To be Affected | N28: DUB EFI Absolute Return Aggregate | O28: =VLOOKUP(A28,'Audit AUM File'!A:B,2,FALSE) -> 2.9118194e+08 | R28: =+IF(D28="",VLOOKUP(A28,'[2]Pivot for Jun AUM'!$A$5:$B$121,2,FALSE)) -> FALSE | S28: =+IF(D28<>"",VLOOKUP(A28,'[2]Total AUM Data'!$A$2:$G$48,7,FALSE)) -> 2.9050311e+08
A29: PF88300 | B29: Yes | C29: ASI - PROGETTO AZIONE ENERGY TRANSITION | D29: Fund | E29: On Original Risk List | F29: From Risk - Fund Responsibility - Dublin Funds | G29: Outcome Oriented Strategies | H29: Risk Accumulation | I29: EFI Absolute Return | K29: AMUNDI.IRL/INV/MAS/PMG/PMG | L29: CASEY RICHARD | M29: To be Affected | N29: DUB EFI Absolute Return Aggregate | O29: 0 | P29: =VLOOKUP(A29,[3]AUM!$A$3:$B$132,2,0) -> 4.5198023e+08 | R29: =+IF(D29="",VLOOKUP(A29,'[2]Pivot for Jun AUM'!$A$5:$B$121,2,FALSE)) -> FALSE | T29: =VLOOKUP(A29,[4]Flows!$A$3:$D$1206,4,0) -> -75897228 | U29: =VLOOKUP(A29,'[3]Last Aum File'!$A$2:$B$128,2,0) -> 5.5549507e+08 | V29: =+U29/1000000 -> 555.49507 | W29: =+IF(OR(A29="HF11",A29="PACIFAI"),0,IF(A29="MUSG",P29-U29/2,P29-U29)) -> -1.0351484e+08 | X29: =+IF(ISNA(W29),0,W29) -> -1.0351484e+08 | Y29: =P29/1000000 -> 451.98023 | Z29: =X29/1000000 -> -103.51484 | AA29: =T29/1000000 -> -75.897228 | AB29: =VLOOKUP(A29,[3]AUM!$A$3:$B$131,2,0)/1000000 -> 451.98023 | AC29: =VLOOKUP(A29,'[3]Last Aum File'!$A$2:$B$126,2,0)/1000000 -> 555.49507 | AD29: =AB29-AC29 -> -103.51484
A30: PF89408 | B30: Yes | C30: ASI - PROGETTO AZIONE ENERGY TRANSITION (II) | D30: Fund | E30: On Original Risk List | F30: From Risk - Fund Responsibility - Dublin Funds | G30: Outcome Oriented Strategies | H30: Risk Accumulation | I30: EFI Absolute Return | K30: AMUNDI.IRL/INV/MAS/PMG/PMG | L30: CASEY RICHARD | M30: To be Affected | N30: DUB EFI Absolute Return Aggregate | O30: 0 | P30: =VLOOKUP(A30,[3]AUM!$A$3:$B$131,2,0) -> 2.7793822e+08 | R30: =+IF(D30="",VLOOKUP(A30,'[2]Pivot for Jun AUM'!$A$5:$B$121,2,FALSE)) -> FALSE | T30: =VLOOKUP(A30,[4]Flows!$A$3:$D$1206,4,0) -> -47534278 | U30: =VLOOKUP(A30,'[3]Last Aum File'!$A$2:$B$128,2,0) -> 3.4182237e+08 | V30: =+U30/1000000 -> 341.82237 | W30: =+IF(OR(A30="HF11",A30="PACIFAI"),0,IF(A30="MUSG",P30-U30/2,P30-U30)) -> -63884148 | X30: =+IF(ISNA(W30),0,W30) -> -63884148 | Y30: =P30/1000000 -> 277.93822 | Z30: =X30/1000000 -> -63.884148 | AA30: =T30/1000000 -> -47.534278 | AB30: =VLOOKUP(A30,[3]AUM!$A$3:$B$131,2,0)/1000000 -> 277.93822 | AC30: =VLOOKUP(A30,'[3]Last Aum File'!$A$2:$B$126,2,0)/1000000 -> 341.82237 | AD30: =AB30-AC30 -> -63.884148
A31: E224 | B31: Yes | C31: PI INVESTMENT FUNDS - TACTICAL ALLOCATION PILLAR - E | D31: Fund | E31: On Original Risk List | F31: =VLOOKUP(A31,'[1]Dublin funds'!$B$2:$AS$153,2,FALSE) -> From Risk - Fund Responsibility - Dublin Funds | G31: =VLOOKUP($A31,'[2]Total AUM Data'!$A:$I,5,FALSE) -> Service Fund | H31: =VLOOKUP($A31,'[2]Total AUM Data'!$A:$I,6,FALSE) -> Income | I31: =VLOOKUP($A31,'[1]Dublin funds'!$B$2:$AS$153,3,FALSE) -> TBD | J31: =VLOOKUP($A31,'[1]Dublin funds'!$B$2:$AS$153,4,FALSE) -> Agreed a light touch with VaR and Leverage limits | K31: AMUNDI.IRL/INV/MAS/PMG/PMG | L31: CASEY RICHARD | M31: To be Affected | N31: To Be Determined | O31: =VLOOKUP(A31,'Audit AUM File'!A:B,2,FALSE) -> 3.365189e+08 | P31: =VLOOKUP(A31,[3]AUM!$A$3:$B$131,2,0) -> 59556669 | R31: =+IF(D31="",VLOOKUP(A31,'[2]Pivot for Jun AUM'!$A$5:$B$121,2,FALSE)) -> FALSE | S31: =+IF(D31<>"",VLOOKUP(A31,'[2]Total AUM Data'!$A$2:$G$48,7,FALSE)) -> 3.6737659e+08 | T31: =VLOOKUP(A31,[4]Flows!$A$3:$D$1206,4,0) -> -6138586.8 | U31: =VLOOKUP(A31,'[3]Last Aum File'!$A$2:$B$128,2,0) -> 74824882 | V31: =+U31/1000000 -> 74.824882 | W31: =+IF(OR(A31="HF11",A31="PACIFAI"),0,IF(A31="MUSG",P31-U31/2,P31-U31)) -> -15268212 | X31: =+IF(ISNA(W31),0,W31) -> -15268212 | Y31: =P31/1000000 -> 59.556669 | Z31: =X31/1000000 -> -15.268212 | AA31: =T31/1000000 -> -6.1385868 | AB31: =VLOOKUP(A31,[3]AUM!$A$3:$B$131,2,0)/1000000 -> 59.556669 | AC31: =VLOOKUP(A31,'[3]Last Aum File'!$A$2:$B$126,2,0)/1000000 -> 74.824882 | AD31: =AB31-AC31 -> -15.268212
A32: E208 | B32: Yes | C32: PI INVESTMENT FUNDS - TACTICAL ALLOCATION BOND FUND - H | D32: Fund | E32: On Original Risk List | F32: =VLOOKUP(A32,'[1]Dublin funds'!$B$2:$AS$153,2,FALSE) -> From Risk - Fund Responsibility - Dublin Funds | G32: =VLOOKUP($A32,'[2]Total AUM Data'!$A:$I,5,FALSE) -> Service Fund | H32: =VLOOKUP($A32,'[2]Total AUM Data'!$A:$I,6,FALSE) -> Bond | I32: =VLOOKUP($A32,'[1]Dublin funds'!$B$2:$AS$153,3,FALSE) -> TBD | J32: =VLOOKUP($A32,'[1]Dublin funds'!$B$2:$AS$153,4,FALSE) -> Agreed a light touch with VaR and Leverage limits | K32: AMUNDI.IRL/INV/MAS/PMG/PMG | L32: PAQUOT BERTRAND | M32: To be Affected | N32: To Be Determined | O32: =VLOOKUP(A32,'Audit AUM File'!A:B,2,FALSE) -> 1.9991382e+08 | P32: =VLOOKUP(A32,[3]AUM!$A$3:$B$131,2,0) -> 74247836 | R32: =+IF(D32="",VLOOKUP(A32,'[2]Pivot for Jun AUM'!$A$5:$B$121,2,FALSE)) -> FALSE | S32: =+IF(D32<>"",VLOOKUP(A32,'[2]Total AUM Data'!$A$2:$G$48,7,FALSE)) -> 4.5036569e+08 | T32: =VLOOKUP(A32,[4]Flows!$A$3:$D$1206,4,0) -> -2977460.7 | U32: =VLOOKUP(A32,'[3]Last Aum File'!$A$2:$B$128,2,0) -> 77232790 | V32: =+U32/1000000 -> 77.23279 | W32: =+IF(OR(A32="HF11",A32="PACIFAI"),0,IF(A32="MUSG",P32-U32/2,P32-U32)) -> -2984954.1 | X32: =+IF(ISNA(W32),0,W32) -> -2984954.1 | Y32: =P32/1000000 -> 74.247836 | Z32: =X32/1000000 -> -2.9849541 | AA32: =T32/1000000 -> -2.9774607 | AB32: =VLOOKUP(A32,[3]AUM!$A$3:$B$131,2,0)/1000000 -> 74.247836 | AC32: =VLOOKUP(A32,'[3]Last Aum File'!$A$2:$B$126,2,0)/1000000 -> 77.23279 | AD32: =AB32-AC32 -> -2.9849541
A33: ULECSTARS | B33: Yes | C33: UL Global Equity Dividend & Subordinated | D33: Model | E33: On Original Risk List | F33: From Risk - Fund Responsibility - Dublin Funds | G33: Allocation Driven Strategies | H33: Equity | I33: TBD | K33: AMUNDI.IRL/INV/MAS/PMG/PMG | L33: PAQUOT BERTRAND | M33: To be Affected | N33: To Be Determined | P33: =VLOOKUP(A33,[3]AUM!$A$3:$B$131,2,0) -> 1901251614 | R33: =+IF(D33="",VLOOKUP(A33,'[2]Pivot for Jun AUM'!$A$5:$B$121,2,FALSE)) -> FALSE | T33: =VLOOKUP(A33,[4]Flows!$A$3:$D$1206,4,0) -> -32352755 | U33: =VLOOKUP(A33,'[3]Last Aum File'!$A$2:$B$1262,2,0) -> 1877332566 | V33: =+U33/1000000 -> 1877.3326 | W33: =+IF(OR(A33="HF11",A33="PACIFAI"),0,IF(A33="MUSG",P33-U33/2,P33-U33)) -> 23919048 | X33: =+IF(ISNA(W33),0,W33) -> 23919048 | Y33: =P33/1000000 -> 1901.2516 | Z33: =X33/1000000 -> 23.919048 | AA33: =T33/1000000 -> -32.352755 | AB33: =VLOOKUP(A33,[3]AUM!$A$3:$B$131,2,0)/1000000 -> 1901.2516 | AC33: =VLOOKUP(A33,'[3]Last Aum File'!$A$2:$B$126,2,0)/1000000 -> 1877.3326 | AD33: =AB33-AC33 -> 23.919048
A34: F100123 | B34: Yes | C34: Amundi Env and Climate Change Sol Fund | D34: Fund | E34: On Original Risk List | F34: From Risk - Fund Responsibility - Dublin Funds | G34: Allocation Driven Strategies | H34: Equity | I34: TBD | K34: AMUNDI.IRL/INV/MAS/PMG/PMG | L34: NICHOLAS POTHIER | M34: To be Affected | N34: To Be Determined | P34: =VLOOKUP(A34,[3]AUM!$A$3:$B$131,2,0)/163 -> 66105969 | R34: =+IF(D34="",VLOOKUP(A34,'[2]Pivot for Jun AUM'!$A$5:$B$121,2,FALSE)) -> FALSE | T34: =P34-U34 -> -14474434 | U34: =VLOOKUP(A34,'[3]Last Aum File'!$A$2:$B$1262,2,0)/163 -> 80580403 | V34: =+U34/1000000 -> 80.580403 | W34: =+IF(OR(A34="HF11",A34="PACIFAI"),0,IF(A34="MUSG",P34-U34/2,P34-U34)) -> -14474434 | X34: =+IF(ISNA(W34),0,W34) -> -14474434 | Y34: =P34/1000000 -> 66.105969 | Z34: =X34/1000000 -> -14.474434 | AA34: =T34/1000000 -> -14.474434 | AB34: =VLOOKUP(A34,[3]AUM!$A$3:$B$131,2,0)/1000000 -> 10775.273 | AC34: =VLOOKUP(A34,'[3]Last Aum File'!$A$2:$B$126,2,0)/1000000 -> 13134.606 | AD34: =AB34-AC34 -> -2359.3327
A35: UDM6 | B35: Yes | C35: Unidiamond + Azionaria America | D35: Model | E35: On Original Risk List | F35: From Risk - Fund Responsibility - Dublin Funds | G35: Allocation Driven Strategies | H35: Equity | I35: TBD | K35: AMUNDI.IRL/INV/MAS/PMG/PMG | L35: PAQUOT BERTRAND | M35: To be Affected | N35: To Be Determined | P35: =VLOOKUP(A35,[3]AUM!$A$3:$B$131,2,0) -> 1100006489 | R35: =+IF(D35="",VLOOKUP(A35,'[2]Pivot for Jun AUM'!$A$5:$B$121,2,FALSE)) -> FALSE | T35: =VLOOKUP(A35,[4]Flows!$A$3:$D$1206,4,0) -> 1008111.9 | U35: =VLOOKUP(A35,'[3]Last Aum File'!$A$2:$B$1262,2,0) -> 1020119648 | V35: =+U35/1000000 -> 1020.1196 | W35: =+IF(OR(A35="HF11",A35="PACIFAI"),0,IF(A35="MUSG",P35-U35/2,P35-U35)) -> 79886841 | X35: =+IF(ISNA(W35),0,W35) -> 79886841 | Y35: =P35/1000000 -> 1100.0065 | Z35: =X35/1000000 -> 79.886841 | AA35: =T35/1000000 -> 1.0081119 | AB35: =VLOOKUP(A35,[3]AUM!$A$3:$B$131,2,0)/1000000 -> 1100.0065 | AC35: =VLOOKUP(A35,'[3]Last Aum File'!$A$2:$B$126,2,0)/1000000 -> 1020.1196 | AD35: =AB35-AC35 -> 79.886841
A36: UDM7 | B36: Yes | C36: Life Program Azionario Pacifico | D36: Model | E36: On Original Risk List | F36: From Risk - Fund Responsibility - Dublin Funds | G36: Allocation Driven Strategies | H36: Equity | I36: TBD | K36: AMUNDI.IRL/INV/MAS/PMG/PMG | L36: PAQUOT BERTRAND | M36: To be Affected | N36: To Be Determined | P36: =VLOOKUP(A36,[3]AUM!$A$3:$B$131,2,0) -> 46360523 | R36: =+IF(D36="",VLOOKUP(A36,'[2]Pivot for Jun AUM'!$A$5:$B$121,2,FALSE)) -> FALSE | T36: =VLOOKUP(A36,[4]Flows!$A$3:$D$1206,4,0) -> -74993.42 | U36: =VLOOKUP(A36,'[3]Last Aum File'!$A$2:$B$1262,2,0) -> 49761394 | V36: =+U36/1000000 -> 49.761394 | W36: =+IF(OR(A36="HF11",A36="PACIFAI"),0,IF(A36="MUSG",P36-U36/2,P36-U36)) -> -3400871 | X36: =+IF(ISNA(W36),0,W36) -> -3400871 | Y36: =P36/1000000 -> 46.360523 | Z36: =X36/1000000 -> -3.400871 | AA36: =T36/1000000 -> -0.07499342 | AB36: =VLOOKUP(A36,[3]AUM!$A$3:$B$131,2,0)/1000000 -> 46.360523 | AC36: =VLOOKUP(A36,'[3]Last Aum File'!$A$2:$B$126,2,0)/1000000 -> 49.761394 | AD36: =AB36-AC36 -> -3.400871
A37: UDM9 | B37: Yes | C37: Unidiamond + Azionaria Intl | D37: Model | E37: On Original Risk List | F37: From Risk - Fund Responsibility - Dublin Funds | G37: Allocation Driven Strategies | H37: Equity | I37: TBD | K37: AMUNDI.IRL/INV/MAS/PMG/PMG | L37: PAQUOT BERTRAND | M37: To be Affected | N37: To Be Determined | P37: =VLOOKUP(A37,[3]AUM!$A$3:$B$131,2,0) -> 173792904 | R37: =+IF(D37="",VLOOKUP(A37,'[2]Pivot for Jun AUM'!$A$5:$B$121,2,FALSE)) -> FALSE | T37: =VLOOKUP(A37,[4]Flows!$A$3:$D$1206,4,0) -> -4429190.5 | U37: =VLOOKUP(A37,'[3]Last Aum File'!$A$2:$B$1262,2,0) -> 173466024 | V37: =+U37/1000000 -> 173.46602 | W37: =+IF(OR(A37="HF11",A37="PACIFAI"),0,IF(A37="MUSG",P37-U37/2,P37-U37)) -> 326880 | X37: =+IF(ISNA(W37),0,W37) -> 326880 | Y37: =P37/1000000 -> 173.7929 | Z37: =X37/1000000 -> 0.32688 | AA37: =T37/1000000 -> -4.4291905 | AB37: =VLOOKUP(A37,[3]AUM!$A$3:$B$131,2,0)/1000000 -> 173.7929 | AC37: =VLOOKUP(A37,'[3]Last Aum File'!$A$2:$B$126,2,0)/1000000 -> 173.46602 | AD37: =AB37-AC37 -> 0.32688
A38: E207 | B38: Yes | C38: PI INVESTMENT FUNDS - TACTICAL ALLOCATION FUND - H | D38: Fund | E38: On Original Risk List | F38: =VLOOKUP(A38,'[1]Dublin funds'!$B$2:$AS$153,2,FALSE) -> From Risk - Fund Responsibility - Dublin Funds | G38: =VLOOKUP($A38,'[2]Total AUM Data'!$A:$I,5,FALSE) -> Service Fund | H38: =VLOOKUP($A38,'[2]Total AUM Data'!$A:$I,6,FALSE) -> Equity | I38: =VLOOKUP($A38,'[1]Dublin funds'!$B$2:$AS$153,3,FALSE) -> TBD | J38: =VLOOKUP($A38,'[1]Dublin funds'!$B$2:$AS$153,4,FALSE) -> Agreed a light touch with VaR and Leverage limits | K38: AMUNDI.IRL/INV/MAS/PMG/PMG | L38: PAQUOT BERTRAND | M38: To be Affected | N38: To Be Determined | O38: =VLOOKUP(A38,'Audit AUM File'!A:B,2,FALSE) -> 1.0311371e+08 | P38: =VLOOKUP(A38,[3]AUM!$A$3:$B$131,2,0) -> 53160978 | R38: =+IF(D38="",VLOOKUP(A38,'[2]Pivot for Jun AUM'!$A$5:$B$121,2,FALSE)) -> FALSE | S38: =+IF(D38<>"",VLOOKUP(A38,'[2]Total AUM Data'!$A$2:$G$48,7,FALSE)) -> 3.1667136e+08 | T38: =VLOOKUP(A38,[4]Flows!$A$3:$D$1206,4,0) -> -446651.58 | U38: =VLOOKUP(A38,'[3]Last Aum File'!$A$2:$B$1262,2,0) -> 56764605 | V38: =+U38/1000000 -> 56.764605 | W38: =+IF(OR(A38="HF11",A38="PACIFAI"),0,IF(A38="MUSG",P38-U38/2,P38-U38)) -> -3603626.9 | X38: =+IF(ISNA(W38),0,W38) -> -3603626.9 | Y38: =P38/1000000 -> 53.160978 | Z38: =X38/1000000 -> -3.6036269 | AA38: =T38/1000000 -> -0.44665158 | AB38: =VLOOKUP(A38,[3]AUM!$A$3:$B$131,2,0)/1000000 -> 53.160978 | AC38: =VLOOKUP(A38,'[3]Last Aum File'!$A$2:$B$126,2,0)/1000000 -> 56.764605 | AD38: =AB38-AC38 -> -3.6036269
